<?xml version="1.0" ?>
<!-- =================================================================================== -->
<!-- |    This document was autogenerated by xacro from /home/alebenassi/Giraffe-robot/src/giraffe_files/urdf/giraffe_robot.urdf.xacro | -->
<!-- |    EDITING THIS FILE BY HAND IS NOT RECOMMENDED                                 | -->
<!-- =================================================================================== -->
<robot name="giraffe_robot">
  <!-- materials -->
  <!-- grey for links, blue for joints -->
  <material name="Blue">
    <color rgba="0 0 0.8 1"/>
  </material>
  <material name="Grey">
    <color rgba="0.5 0.5 0.5 1"/>
  </material>
  <material name="White">
    <color rgba="1 1 1 1"/>
  </material>
  <material name="Black">
    <color rgba="0 0 0 1"/>
  </material>
  <link name="world"/>
  <!-- floor 5x12 -->
  <link name="floor">
    <visual>
      <geometry>
        <box size="5 12 0.01"/>
        <!-- thin plane -->
      </geometry>
      <origin rpy="0 0 0" xyz="2.5 6 0"/>
      <material name="Grey"/>
    </visual>
  </link>
  <joint name="world_floor" type="fixed">
    <parent link="world"/>
    <child link="floor"/>
    <origin rpy="0 0 0" xyz="0 0 0"/>
  </joint>
  <!-- world reference set at the center of the ceiling-->
  <joint name="world_base" type="fixed">
    <parent link="world"/>
    <child link="base_link"/>
    <origin rpy="0 0 0" xyz="2.5 6.0 4.0"/>
  </joint>
  <!-- base link (on the ceiling) -->
  <link name="base_link">
    <visual>
      <geometry>
        <box size="0.2 0.2 0.05"/>
      </geometry>
      <material name="Grey"/>
    </visual>
  </link>
  <!-- yaw link (z axis) and joint -->
  <link name="yaw_link">
    <visual>
      <geometry>
        <sphere radius="0.05"/>
      </geometry>
      <material name="White"/>
    </visual>
  </link>
  <joint name="yaw_joint" type="revolute">
    <parent link="base_link"/>
    <child link="yaw_link"/>
    <origin rpy="0 0 0" xyz="0 0 0"/>
    <axis xyz="0 0 1"/>
    <limit effort="10" lower="-3.141592653589793" upper="3.141592653589793" velocity="1"/>
  </joint>
  <!-- pitch link (y axis) and joint -->
  <link name="pitch_link">
    <visual>
      <geometry>
        <sphere radius="0.05"/>
      </geometry>
      <origin rpy="0 1.5707963267948966 0" xyz="0 0 0"/>
      <material name="White"/>
    </visual>
  </link>
  <joint name="pitch_joint" type="revolute">
    <parent link="yaw_link"/>
    <child link="pitch_link"/>
    <origin rpy="0 0 0" xyz="0 0 0"/>
    <axis xyz="0 1 0"/>
    <limit effort="10" lower="-1.0471975511965976" upper="0" velocity="1"/>
    <!-- 30 degrees is enough, no need to arrive to the ceiling -->
  </joint>
  <!-- prismatic link and joint -->
  <link name="prismatic_link">
    <visual>
      <origin rpy="0 0 0" xyz="0 0 -2.75"/>
      <geometry>
        <cylinder length="5.5" radius="0.05"/>
      </geometry>
      <material name="White"/>
    </visual>
  </link>
  <joint name="prismatic_joint" type="prismatic">
    <parent link="pitch_link"/>
    <child link="prismatic_link"/>
    <origin rpy="0 0 0" xyz="0 0 0"/>
    <axis xyz="0 0 1"/>
    <limit effort="100" lower="0.0" upper="5.5" velocity="0.5"/>
  </joint>
  <!-- microphone wrist link and 2 joints -->
  <link name="wrist1_link">
    <visual>
      <geometry>
        <cylinder length="1" radius="0.05"/>
      </geometry>
      <origin rpy="0 0 0" xyz="0 0 -0.5"/>
      <material name="White"/>
    </visual>
  </link>
  <joint name="wrist1" type="revolute">
    <parent link="prismatic_link"/>
    <child link="wrist1_link"/>
    <origin rpy="0 0 0" xyz="0 0 -5.5"/>
    <axis xyz="0 1 0"/>
    <limit effort="5" lower="-1.5707963267948966" upper="1.5707963267948966" velocity="1"/>
  </joint>
  <joint name="wrist2" type="revolute">
    <parent link="wrist1_link"/>
    <child link="microphone"/>
    <origin rpy="0 0 0" xyz="0 0 -1"/>
    <axis xyz="0 1 0"/>
    <limit effort="5" lower="-1.5707963267948966" upper="1.5707963267948966" velocity="1"/>
  </joint>
  <!-- microphone (end effector) -->
  <link name="microphone">
    <visual>
      <geometry>
        <sphere radius="0.015"/>
      </geometry>
      <material name="Black"/>
    </visual>
    <visual>
      <geometry>
        <cylinder length="0.1" radius="0.02"/>
      </geometry>
      <origin rpy="0 0 0" xyz="0 0 -0.065"/>
      <material name="Grey"/>
    </visual>
    <visual>
      <geometry>
        <sphere radius="0.03"/>
      </geometry>
      <origin rpy="0 0 0" xyz="0 0 -0.145"/>
      <material name="Black"/>
    </visual>
  </link>
</robot>
