<?xml version="1.0" ?>
<!-- =================================================================================== -->
<!-- |    This document was autogenerated by xacro from giraffe_robot.xacro            | -->
<!-- |    EDITING THIS FILE BY HAND IS NOT RECOMMENDED                                 | -->
<!-- =================================================================================== -->
<robot name="giraffe_robot">
  <!-- materials -->
  <material name="Blue">
    <color rgba="0 0 0.8 1"/>
  </material>
  <material name="Grey">
    <color rgba="0.5 0.5 0.5 1"/>
  </material>
  <material name="White">
    <color rgba="1 1 1 1"/>
  </material>
  <material name="Black">
    <color rgba="0 0 0 1"/>
  </material>
  <!-- cylinder+sphere volume -->
  <link name="world"/>
  <!--floor 5x12 -->
  <link name="floor">
    <visual>
      <geometry>
        <box size="5 12 0.01"/>
        <!-- thin plane -->
      </geometry>
      <origin rpy="0 0 0" xyz="2.5 6 -0.005"/>
      <!-- in -z to perfectly center it -->
      <material name="Grey"/>
    </visual>
  </link>
  <joint name="world_floor" type="fixed">
    <parent link="world"/>
    <child link="floor"/>
    <origin rpy="0 0 0" xyz="0 0 0"/>
  </joint>
  <!-- base link (on the ceiling) -->
  <link name="base_link">
    <visual>
      <geometry>
        <box size="0.2 0.2 0.05"/>
      </geometry>
      <material name="Grey"/>
    </visual>
  </link>
  <!-- world reference set at the center of the ceiling-->
  <joint name="world_base" type="fixed">
    <parent link="world"/>
    <child link="base_link"/>
    <origin rpy="0 0 0" xyz="2.5 6.0 4.0"/>
  </joint>
  <!-- yaw link (z axis) and joint -->
  <link name="yaw_link">
    <visual>
      <geometry>
        <sphere radius="0.05"/>
      </geometry>
      <material name="White"/>
    </visual>
    <inertial>
      <mass value="0.7068583470577036"/>
      <origin rpy="0 0 0" xyz="0.0 0.0 0.0"/>
      <!-- position in the center -->
      <inertia ixx="0.0007068583470577037" ixy="0.0" ixz="0.0" iyy="0.0007068583470577037" iyz="0.0" izz="0.0007068583470577037"/>
      <!-- inertia formula for full spheres -->
    </inertial>
  </link>
  <joint name="yaw_joint" type="revolute">
    <parent link="base_link"/>
    <child link="yaw_link"/>
    <origin rpy="0 0 0" xyz="0.0 0.0 -0.07500000000000001"/>
    <axis xyz="0 0 1"/>
    <limit effort="10" lower="-3.141592653589793" upper="3.141592653589793" velocity="1"/>
  </joint>
  <!-- pitch link (y axis) and joint -->
  <link name="pitch_link">
    <visual>
      <geometry>
        <sphere radius="0.05"/>
      </geometry>
      <origin rpy="0 1.5707963267948966 0" xyz="0 0 0"/>
      <material name="White"/>
    </visual>
    <inertial>
      <mass value="0.7068583470577036"/>
      <origin rpy="0 1.5707963267948966 0" xyz="0.0 0.0 0.0"/>
      <!-- position in the center -->
      <inertia ixx="0.0007068583470577037" ixy="0.0" ixz="0.0" iyy="0.0007068583470577037" iyz="0.0" izz="0.0007068583470577037"/>
      <!-- inertia formula for spheres -->
    </inertial>
  </link>
  <joint name="pitch_joint" type="revolute">
    <parent link="yaw_link"/>
    <child link="pitch_link"/>
    <origin rpy="0 0 0" xyz="0 0 0"/>
    <axis xyz="0 1 0"/>
    <limit effort="10" lower="-1.5707963267948966" upper="1.5707963267948966" velocity="1"/>
  </joint>
  <!-- prismatic link and joint -->
  <link name="prismatic_link">
    <visual>
      <geometry>
        <cylinder length="5.5" radius="0.05"/>
      </geometry>
      <origin rpy="0 0 0" xyz="0 0 -0.05"/>
      <material name="White"/>
    </visual>
    <inertial>
      <mass value="116.6316272645211"/>
      <origin rpy="0 0 0" xyz="0.0 0.0 -2.75"/>
      <!-- position in the center -->
      <inertia ixx="294.0817884963539" ixy="0.0" ixz="0.0" iyy="294.0817884963539" iyz="0.0" izz="0.1457895340806514"/>
      <!-- inertia formula for cylinders (cylinder axis along z) -->
    </inertial>
    <!-- izz=1/2mr^2 , ixx=iyy=1/12m(3r^2+L^2)-->
  </link>
  <joint name="prismatic_joint" type="prismatic">
    <parent link="pitch_link"/>
    <child link="prismatic_link"/>
    <origin rpy="0 0 0" xyz="0 0 -2.75"/>
    <!--xyz="0 0 -${prismatic_length/2}-->
    <axis xyz="0 0 1"/>
    <limit effort="100" lower="0.0" upper="5.5" velocity="0.5"/>
  </joint>
  <!-- wrist1 link and joint -->
  <link name="wrist1_link">
    <visual>
      <geometry>
        <cylinder length="1" radius="0.05"/>
      </geometry>
      <origin rpy="0 0 0" xyz="0 0 -0.5"/>
      <material name="White"/>
    </visual>
    <inertial>
      <mass value="21.20575041173111"/>
      <origin rpy="0 0 0" xyz="0.0 0.0 -0.5"/>
      <!-- position in the center -->
      <inertia ixx="1.780399461651591" ixy="0.0" ixz="0.0" iyy="1.780399461651591" iyz="0.0" izz="0.026507188014663893"/>
      <!-- inertia formula for cylinders (cylinder axis along z) -->
    </inertial>
  </link>
  <joint name="wrist1" type="revolute">
    <parent link="prismatic_link"/>
    <child link="wrist1_link"/>
    <origin rpy="0 0 0" xyz="0 0 -2.75"/>
    <axis xyz="0 1 0"/>
    <limit effort="5" lower="-1.5707963267948966" upper="1.5707963267948966" velocity="1"/>
  </joint>
  <!-- wrist2 link and joint -->
  <link name="wrist2_link">
    <visual>
      <geometry>
        <sphere radius="0.015"/>
      </geometry>
      <material name="Black"/>
    </visual>
    <inertial>
      <mass value="0.03817035074111598"/>
      <origin rpy="0 0 0" xyz="0.0 0.0 -0.0075"/>
      <!-- position in the center -->
      <inertia ixx="3.435331566700438e-06" ixy="0.0" ixz="0.0" iyy="3.435331566700438e-06" iyz="0.0" izz="3.435331566700438e-06"/>
      <!-- inertia formula for spheres -->
    </inertial>
  </link>
  <joint name="wrist2" type="revolute">
    <parent link="wrist1_link"/>
    <child link="wrist2_link"/>
    <origin rpy="0 0 0" xyz="0 0 -1"/>
    <axis xyz="0 1 0"/>
    <limit effort="5" lower="-1.5707963267948966" upper="1.5707963267948966" velocity="1"/>
  </joint>
  <!-- microphone (end effector) -->
  <link name="microphone">
    <visual>
      <geometry>
        <cylinder length="0.1" radius="0.02"/>
      </geometry>
      <origin rpy="0 0 0" xyz="0 0 0.11"/>
      <material name="Grey"/>
    </visual>
    <visual>
      <geometry>
        <sphere radius="0.03"/>
      </geometry>
      <origin rpy="0 0 0" xyz="0 0 0.03"/>
      <material name="Black"/>
    </visual>
    <inertial>
      <!-- to simplify we approximate the inertia computation to a cylinder with the mic sphere's radius -->
      <mass value="0.24592387292300896"/>
      <origin rpy="0 0 0" xyz="0 0 -0.08"/>
      <!-- center in the center of the approx cylinder (sphere radius+cylinder length)/2 -->
      <inertia ixx="0.00018649227029994846" ixy="0.0" ixz="0.0" iyy="0.00018649227029994846" iyz="0.0" izz="0.00011066574281535402"/>
    </inertial>
  </link>
  <joint name="mic_frame" type="fixed">
    <parent link="wrist2_link"/>
    <child link="microphone"/>
    <origin rpy="0 0 0" xyz="0 0 -0.175"/>
  </joint>
</robot>
